Workbook

Sheet Drivers
B1: Name | C1: Team | D1: Number | E1: Country | F1: Constructor
B2: Pierre Gasly | C2: France BWT Alpine F1 Team | D2: 10 | E2: 🇫🇷 France | F2: Alpine-Mercedes
B3: Franco Colapinto | C3: France BWT Alpine F1 Team | D3: 43 | E3: 🇦🇷 Argentina | F3: Alpine-Mercedes
B4: Fernando Alonso | C4: United Kingdom Aston Martin Aramco F1 Team | D4: 14 | E4: 🇪🇸 Spain | F4: Aston Martin Aramco-Honda
B5: Lance Stroll | C5: United Kingdom Aston Martin Aramco F1 Team | D5: 18 | E5: 🇨🇦 Canada | F5: Aston Martin Aramco-Honda
B6: Alexander Albon | C6: United Kingdom Atlassian Williams F1 Team | D6: 23 | E6: 🇹🇭 Thailand | F6: Atlassian Williams-Mercedes
B7: Carlos Sainz Jr. | C7: United Kingdom Atlassian Williams F1 Team | D7: 55 | E7: 🇪🇸 Spain | F7: Atlassian Williams-Mercedes
B8: Gabriel Bortoleto | C8: Germany Audi Revolut F1 Team | D8: 5 | E8: 🇧🇷 Brazil | F8: Audi
B9: Nico Hülkenberg | C9: Germany Audi Revolut F1 Team | D9: 27 | E9: 🇩🇪 Germany | F9: Audi
B10: Sergio Pérez | C10: United States Cadillac Formula 1 Team | D10: 11 | E10: 🇲🇽 Mexico | F10: Cadillac-Ferrari
B11: Valtteri Bottas | C11: United States Cadillac Formula 1 Team | D11: 77 | E11: 🇫🇮 Finland | F11: Cadillac-Ferrari
B12: Charles Leclerc | C12: Italy Scuderia Ferrari HP | D12: 16 | E12: 🇲🇨 Monaco | F12: Ferrari
B13: Lewis Hamilton | C13: Italy Scuderia Ferrari HP | D13: 44 | E13: 🇬🇧 Great Britain | F13: Ferrari
... B23: Isack Hadjar | C23: Austria Oracle Red Bull Racing | D23: 6 | E23: 🇫🇷 France | F23: Red Bull Racing-Red Bull Ford

Sheet Track_Details
B2: Race Name | C2: Circuit Name | D2: Location | E2: Race Date | F2: Distance | G2: Fastest Time | H2: 1 | I2: 2 | J2: 3
B3: Australian Grand Prix | C3: Albert Park Circuit | D3: Melbourne | E3: 46089 | F3: 5.278
B4: Chinese Grand Prix | C4: Shanghai International Circuit | D4: Shanghai | F4: 5.451
B5: Japanese Grand Prix | C5: Suzuka International Racing Course | D5: Suzuka | F5: 5.807
B6: Bahrain Grand Prix | C6: Bahrain International Circuit | D6: Sakhir | F6: 5.412
B7: Saudi Arabian Grand Prix | C7: Jeddah Corniche Circuit | D7: Jeddah | F7: 6.174
B8: Miami Grand Prix | C8: Miami International Autodrome | D8: Miami Gardens, Florida | F8: 5.412
B9: Emilia Romagna Grand Prix | C9: Imola Circuit | D9: Imola | F9: 4.909
B10: Monaco Grand Prix | C10: Circuit de Monaco | D10: Monaco | F10: 3.337
B11: Spanish Grand Prix | C11: Circuit de Barcelona-Catalunya | D11: Montmeló | F11: 4.675
B12: Canadian Grand Prix | C12: Circuit Gilles Villeneuve | D12: Montreal | F12: 4.361
B13: Austrian Grand Prix | C13: Red Bull Ring | D13: Spielberg | F13: 4.318
B14: British Grand Prix | C14: Silverstone Circuit | D14: Silverstone | F14: 5.891
B15: Belgian Grand Prix | C15: Circuit de Spa-Francorchamps | D15: Stavelot | F15: 7.004
... B26: Abu Dhabi Grand Prix | C26: Yas Marina Circuit | D26: Abu Dhabi | F26: 5.281
B57: Now your table is fully detailed! Let me know if you need any tweaks.

Sheet Track_Log
A1: Driver | B1: Australian Grand Prix | C1: Chinese Grand Prix | D1: Japanese Grand Prix | E1: Bahrain Grand Prix | F1: Saudi Arabian Grand Prix | G1: Miami Grand Prix | H1: Emilia Romagna Grand Prix | I1: Monaco Grand Prix | J1: Spanish Grand Prix | K1: Canadian Grand Prix | L1: Austrian Grand Prix | M1: British Grand Prix | N1: Belgian Grand Prix | O1: Hungarian Grand Prix | P1: Dutch Grand Prix | Q1: Italian Grand Prix | R1: Azerbaijan Grand Prix | S1: Singapore Grand Prix | T1: United States Grand Prix | U1: Mexico City Grand Prix | V1: São Paulo Grand Prix | W1: Las Vegas Grand Prix | X1: Qatar Grand Prix | Y1: Abu Dhabi Grand Prix
B2: Start | C2: Start | D2: Start | E2: Start | F2: Start | G2: Start | H2: Start | I2: Start | J2: Start | K2: Start | L2: Start | M2: Start | N2: Start | O2: Start | P2: Start | Q2: Start | R2: Start | S2: Start | T2: Start | U2: Start | V2: Start | W2: Start | X2: Start | Y2: Start
A3: Lando Norris | B3: 19
A4: George Russell | B4: 7
A5: Max Verstappen | B5: 3
A6: Lewis Hamilton | B6: 2
A7: Carlos Sainz | B7: 12
A8: Liam Lawson | B8: 13
A9: Fernando Alonso
A10: Esteban Ocon | B10: 11
A11: Nico Hulkenberg | B11: 10
A12: Pierre Gasly | B12: 18
A13: Sergio Pérez | B13: 20
A14: Oscar Piastri | B14: 6
A15: Kimi Antonelli | B15: 8
A16: Isack Hadjar | B16: 4
A17: Charles Leclerc | B17: 1
A18: Alexander Albon | B18: 15
A19: Arvid Lindblad | B19: 5
A20: Lance Stroll | B20: 21
A21: Oliver Bearman | B21: 14
... A24: Valtteri Bottas | B24: 17
B26: End | C26: End | D26: End | E26: End | F26: End | G26: End | H26: End | I26: End | J26: End | K26: End | L26: End | M26: End | N26: End | O26: End | P26: End | Q26: End | R26: End | S26: End | T26: End | U26: End | V26: End | W26: End | X26: End | Y26: End
A27: Lando Norris | B27: 5
A28: George Russell | B28: 1
A29: Max Verstappen | B29: 6
A30: Lewis Hamilton | B30: 4
A31: Carlos Sainz | B31: 15
A32: Liam Lawson | B32: 13
A33: Fernando Alonso | B33: RET
A34: Esteban Ocon | B34: 11
A35: Nico Hulkenberg | B35: DNS
A36: Pierre Gasly | B36: 10
A37: Sergio Pérez | B37: 16
A38: Oscar Piastri | B38: DNS
A39: Kimi Antonelli | B39: 2
A40: Isack Hadjar | B40: RET
A41: Charles Leclerc | B41: 3
A42: Alexander Albon | B42: 12
A43: Arvid Lindblad | B43: 8
...

Sheet Times
A1: Driver | B1: Number | C1: Constructor | D1: Team | E1: Australian Grand Prix | F1: Chinese Grand Prix | G1: Japanese Grand Prix | H1: Bahrain Grand Prix | I1: Saudi Arabian Grand Prix | J1: Miami Grand Prix | K1: Emilia Romagna Grand Prix | L1: Monaco Grand Prix | M1: Spanish Grand Prix | N1: Canadian Grand Prix | O1: Austrian Grand Prix | P1: British Grand Prix | Q1: Belgian Grand Prix | R1: Hungarian Grand Prix | S1: Dutch Grand Prix | T1: Italian Grand Prix | U1: Azerbaijan Grand Prix | V1: Singapore Grand Prix | W1: United States Grand Prix | X1: Mexico City Grand Prix | Y1: São Paulo Grand Prix | Z1: Las Vegas Grand Prix | AA1: Qatar Grand Prix | AB1: Abu Dhabi Grand Prix
E2: Qual | F2: Qual | G2: Qual | H2: Qual | I2: Qual | J2: Qual | K2: Qual | L2: Qual | M2: Qual | N2: Qual | O2: Qual | P2: Qual | Q2: Qual | R2: Qual | S2: Qual | T2: Qual | U2: Qual | V2: Qual | W2: Qual | X2: Qual | Y2: Qual | Z2: Qual | AA2: Qual | AB2: Qual
A3: Pierre Gasly | B3: {=_xlfn._xlws.FILTER(Drivers!D:D,Drivers!B:B=Table6[[#This Row],[Driver]],0)} -> 10 | C3: =_xlfn.XLOOKUP(A3,Constructor!$C$2:$C$23,Constructor!$B$2:$B$23,"") -> Alpine-Mercedes | D3: =_xlfn.XLOOKUP(A3,Constructor!$C$2:$C$23,Constructor!$A$2:$A$23,"") -> France BWT Alpine F1 Team | E3: 3.768
A4: Franco Colapinto | B4: {=_xlfn._xlws.FILTER(Drivers!D:D,Drivers!B:B=Table6[[#This Row],[Driver]],0)} -> 43 | C4: =_xlfn.XLOOKUP(A4,Constructor!$C$2:$C$23,Constructor!$B$2:$B$23,"") -> Alpine-Mercedes | D4: =_xlfn.XLOOKUP(A4,Constructor!$C$2:$C$23,Constructor!$A$2:$A$23,"") -> France BWT Alpine F1 Team | E4: 3.058
A5: Fernando Alonso | B5: {=_xlfn._xlws.FILTER(Drivers!D:D,Drivers!B:B=Table6[[#This Row],[Driver]],0)} -> 14 | C5: =_xlfn.XLOOKUP(A5,Constructor!$C$2:$C$23,Constructor!$B$2:$B$23,"") -> Aston Martin Aramco-Honda | D5: =_xlfn.XLOOKUP(A5,Constructor!$C$2:$C$23,Constructor!$A$2:$A$23,"") -> United Kingdom Aston Martin Aramco F1 Team | E5: 0
A6: Lance Stroll | B6: {=_xlfn._xlws.FILTER(Drivers!D:D,Drivers!B:B=Table6[[#This Row],[Driver]],0)} -> 18 | C6: =_xlfn.XLOOKUP(A6,Constructor!$C$2:$C$23,Constructor!$B$2:$B$23,"") -> Aston Martin Aramco-Honda | D6: =_xlfn.XLOOKUP(A6,Constructor!$C$2:$C$23,Constructor!$A$2:$A$23,"") -> United Kingdom Aston Martin Aramco F1 Team | E6: 30.067
A7: Alexander Albon | B7: {=_xlfn._xlws.FILTER(Drivers!D:D,Drivers!B:B=Table6[[#This Row],[Driver]],0)} -> 23 | C7: =_xlfn.XLOOKUP(A7,Constructor!$C$2:$C$23,Constructor!$B$2:$B$23,"") -> Atlassian Williams-Mercedes | D7: =_xlfn.XLOOKUP(A7,Constructor!$C$2:$C$23,Constructor!$A$2:$A$23,"") -> United Kingdom Atlassian Williams F1 Team | E7: 2.863
A8: Carlos Sainz Jr. | B8: {=_xlfn._xlws.FILTER(Drivers!D:D,Drivers!B:B=Table6[[#This Row],[Driver]],0)} -> 55 | C8: =_xlfn.XLOOKUP(A8,Constructor!$C$2:$C$23,Constructor!$B$2:$B$23,"") -> Atlassian Williams-Mercedes | D8: =_xlfn.XLOOKUP(A8,Constructor!$C$2:$C$23,Constructor!$A$2:$A$23,"") -> United Kingdom Atlassian Williams F1 Team | E8: 2.056
A9: Gabriel Bortoleto | B9: {=_xlfn._xlws.FILTER(Drivers!D:D,Drivers!B:B=Table6[[#This Row],[Driver]],0)} -> 5 | C9: =_xlfn.XLOOKUP(A9,Constructor!$C$2:$C$23,Constructor!$B$2:$B$23,"") -> Audi | D9: =_xlfn.XLOOKUP(A9,Constructor!$C$2:$C$23,Constructor!$A$2:$A$23,"") -> Germany Audi Revolut F1 Team | E9: 1.429
A10: Nico Hülkenberg | B10: {=_xlfn._xlws.FILTER(Drivers!D:D,Drivers!B:B=Table6[[#This Row],[Driver]],0)} -> 27 | C10: =_xlfn.XLOOKUP(A10,Constructor!$C$2:$C$23,Constructor!$B$2:$B$23,"") -> Audi | D10: =_xlfn.XLOOKUP(A10,Constructor!$C$2:$C$23,Constructor!$A$2:$A$23,"") -> Germany Audi Revolut F1 Team | E10: 1.702
A11: Sergio Pérez | B11: {=_xlfn._xlws.FILTER(Drivers!D:D,Drivers!B:B=Table6[[#This Row],[Driver]],0)} -> 11 | C11: =_xlfn.XLOOKUP(A11,Constructor!$C$2:$C$23,Constructor!$B$2:$B$23,"") -> Cadillac-Ferrari | D11: =_xlfn.XLOOKUP(A11,Constructor!$C$2:$C$23,Constructor!$A$2:$A$23,"") -> United States Cadillac Formula 1 Team | E11: 4.353
A12: Valtteri Bottas | B12: {=_xlfn._xlws.FILTER(Drivers!D:D,Drivers!B:B=Table6[[#This Row],[Driver]],0)} -> 77 | C12: =_xlfn.XLOOKUP(A12,Constructor!$C$2:$C$23,Constructor!$B$2:$B$23,"") -> Cadillac-Ferrari | D12: =_xlfn.XLOOKUP(A12,Constructor!$C$2:$C$23,Constructor!$A$2:$A$23,"") -> United States Cadillac Formula 1 Team | E12: 3.755
A13: Charles Leclerc | B13: {=_xlfn._xlws.FILTER(Drivers!D:D,Drivers!B:B=Table6[[#This Row],[Driver]],0)} -> 16 | C13: =_xlfn.XLOOKUP(A13,Constructor!$C$2:$C$23,Constructor!$B$2:$B$23,"") -> Ferrari | D13: =_xlfn.XLOOKUP(A13,Constructor!$C$2:$C$23,Constructor!$A$2:$A$23,"") -> Italy Scuderia Ferrari HP | E13: 0.0009290162 | AC13: =Table6[[#This Row],[Australian Grand Prix]]+E14 -> 0.46992902
A14: Lewis Hamilton | B14: {=_xlfn._xlws.FILTER(Drivers!D:D,Drivers!B:B=Table6[[#This Row],[Driver]],0)} -> 44 | C14: =_xlfn.XLOOKUP(A14,Constructor!$C$2:$C$23,Constructor!$B$2:$B$23,"") -> Ferrari | D14: =_xlfn.XLOOKUP(A14,Constructor!$C$2:$C$23,Constructor!$A$2:$A$23,"") -> Italy Scuderia Ferrari HP | E14: 0.469
A15: Esteban Ocon | B15: {=_xlfn._xlws.FILTER(Drivers!D:D,Drivers!B:B=Table6[[#This Row],[Driver]],0)} -> 31 | C15: =_xlfn.XLOOKUP(A15,Constructor!$C$2:$C$23,Constructor!$B$2:$B$23,"") -> Haas-Ferrari | D15: =_xlfn.XLOOKUP(A15,Constructor!$C$2:$C$23,Constructor!$A$2:$A$23,"") -> United States TGR Haas F1 Team | E15: 1.894
A16: Oliver Bearman | B16: {=_xlfn._xlws.FILTER(Drivers!D:D,Drivers!B:B=Table6[[#This Row],[Driver]],0)} -> 87 | C16: =_xlfn.XLOOKUP(A16,Constructor!$C$2:$C$23,Constructor!$B$2:$B$23,"") -> Haas-Ferrari | D16: =_xlfn.XLOOKUP(A16,Constructor!$C$2:$C$23,Constructor!$A$2:$A$23,"") -> United States TGR Haas F1 Team | E16: 2.415
A17: Lando Norris | B17: {=_xlfn._xlws.FILTER(Drivers!D:D,Drivers!B:B=Table6[[#This Row],[Driver]],0)} -> 1 | C17: =_xlfn.XLOOKUP(A17,Constructor!$C$2:$C$23,Constructor!$B$2:$B$23,"") -> McLaren-Mercedes | D17: =_xlfn.XLOOKUP(A17,Constructor!$C$2:$C$23,Constructor!$A$2:$A$23,"") -> United Kingdom McLaren Mastercard F1 Team | E17: 4.124
A18: Oscar Piastri | B18: {=_xlfn._xlws.FILTER(Drivers!D:D,Drivers!B:B=Table6[[#This Row],[Driver]],0)} -> 81 | C18: =_xlfn.XLOOKUP(A18,Constructor!$C$2:$C$23,Constructor!$B$2:$B$23,"") -> McLaren-Mercedes | D18: =_xlfn.XLOOKUP(A18,Constructor!$C$2:$C$23,Constructor!$A$2:$A$23,"") -> United Kingdom McLaren Mastercard F1 Team | E18: 1.075
A19: Kimi Antonelli | B19: {=_xlfn._xlws.FILTER(Drivers!D:D,Drivers!B:B=Table6[[#This Row],[Driver]],0)} -> 12 | C19: =_xlfn.XLOOKUP(A19,Constructor!$C$2:$C$23,Constructor!$B$2:$B$23,"") -> Mercedes | D19: =_xlfn.XLOOKUP(A19,Constructor!$C$2:$C$23,Constructor!$A$2:$A$23,"") -> Germany Mercedes-AMG Petronas F1 Team | E19: 1.109
A20: George Russell | B20: {=_xlfn._xlws.FILTER(Drivers!D:D,Drivers!B:B=Table6[[#This Row],[Driver]],0)} -> 63 | C20: =_xlfn.XLOOKUP(A20,Constructor!$C$2:$C$23,Constructor!$B$2:$B$23,"") -> Mercedes | D20: =_xlfn.XLOOKUP(A20,Constructor!$C$2:$C$23,Constructor!$A$2:$A$23,"") -> Germany Mercedes-AMG Petronas F1 Team | E20: 1.104
A21: Liam Lawson | B21: {=_xlfn._xlws.FILTER(Drivers!D:D,Drivers!B:B=Table6[[#This Row],[Driver]],0)} -> 30 | C21: =_xlfn.XLOOKUP(A21,Constructor!$C$2:$C$23,Constructor!$B$2:$B$23,"") -> Racing Bulls-Red Bull Ford | D21: =_xlfn.XLOOKUP(A21,Constructor!$C$2:$C$23,Constructor!$A$2:$A$23,"") -> Italy Visa Cash App Racing Bulls F1 Team | E21: 2.346
A22: Arvid Lindblad | B22: {=_xlfn._xlws.FILTER(Drivers!D:D,Drivers!B:B=Table6[[#This Row],[Driver]],0)} -> 41 | C22: =_xlfn.XLOOKUP(A22,Constructor!$C$2:$C$23,Constructor!$B$2:$B$23,"") -> Racing Bulls-Red Bull Ford | D22: =_xlfn.XLOOKUP(A22,Constructor!$C$2:$C$23,Constructor!$A$2:$A$23,"") -> Italy Visa Cash App Racing Bulls F1 Team | E22: 1.046
A23: Max Verstappen | B23: {=_xlfn._xlws.FILTER(Drivers!D:D,Drivers!B:B=Table6[[#This Row],[Driver]],0)} -> 3 | C23: =_xlfn.XLOOKUP(A23,Constructor!$C$2:$C$23,Constructor!$B$2:$B$23,"") -> Red Bull Racing-Red Bull Ford | D23: =_xlfn.XLOOKUP(A23,Constructor!$C$2:$C$23,Constructor!$A$2:$A$23,"") -> Austria Oracle Red Bull Racing | E23: 0.522
A24: Isack Hadjar | B24: {=_xlfn._xlws.FILTER(Drivers!D:D,Drivers!B:B=Table6[[#This Row],[Driver]],0)} -> 6 | C24: =_xlfn.XLOOKUP(A24,Constructor!$C$2:$C$23,Constructor!$B$2:$B$23,"") -> Red Bull Racing-Red Bull Ford | D24: =_xlfn.XLOOKUP(A24,Constructor!$C$2:$C$23,Constructor!$A$2:$A$23,"") -> Austria Oracle Red Bull Racing | E24: 0.82
C25: =_xlfn.XLOOKUP(A25,Constructor!$C$2:$C$23,Constructor!$B$2:$B$23,"") | D25: =_xlfn.XLOOKUP(A25,Constructor!$C$2:$C$23,Constructor!$A$2:$A$23,"")
E26: Race | F26: Race | G26: Race | H26: Race | I26: Race | J26: Race | K26: Race | L26: Race | M26: Race | N26: Race | O26: Race | P26: Race | Q26: Race | R26: Race | S26: Race | T26: Race | U26: Race | V26: Race | W26: Race | X26: Race | Y26: Race | Z26: Race | AA26: Race | AB26: Race
A27: Pierre Gasly | B27: {=_xlfn._xlws.FILTER(Drivers!D:D,Drivers!B:B=Table6[[#This Row],[Driver]],0)} -> 10 | C27: =_xlfn.XLOOKUP(A27,Constructor!$C$2:$C$23,Constructor!$B$2:$B$23,"") -> Alpine-Mercedes | D27: =_xlfn.XLOOKUP(A27,Constructor!$C$2:$C$23,Constructor!$A$2:$A$23,"") -> France BWT Alpine F1 Team | E27: +1 lap
A28: Franco Colapinto | B28: {=_xlfn._xlws.FILTER(Drivers!D:D,Drivers!B:B=Table6[[#This Row],[Driver]],0)} -> 43 | C28: =_xlfn.XLOOKUP(A28,Constructor!$C$2:$C$23,Constructor!$B$2:$B$23,"") -> Alpine-Mercedes | D28: =_xlfn.XLOOKUP(A28,Constructor!$C$2:$C$23,Constructor!$A$2:$A$23,"") -> France BWT Alpine F1 Team | E28: +2 laps
A29: Fernando Alonso | B29: {=_xlfn._xlws.FILTER(Drivers!D:D,Drivers!B:B=Table6[[#This Row],[Driver]],0)} -> 14 | C29: =_xlfn.XLOOKUP(A29,Constructor!$C$2:$C$23,Constructor!$B$2:$B$23,"") -> Aston Martin Aramco-Honda | D29: =_xlfn.XLOOKUP(A29,Constructor!$C$2:$C$23,Constructor!$A$2:$A$23,"") -> United Kingdom Aston Martin Aramco F1 Team | E29: DNF
A30: Lance Stroll | B30: {=_xlfn._xlws.FILTER(Drivers!D:D,Drivers!B:B=Table6[[#This Row],[Driver]],0)} -> 18 | C30: =_xlfn.XLOOKUP(A30,Constructor!$C$2:$C$23,Constructor!$B$2:$B$23,"") -> Aston Martin Aramco-Honda | D30: =_xlfn.XLOOKUP(A30,Constructor!$C$2:$C$23,Constructor!$A$2:$A$23,"") -> United Kingdom Aston Martin Aramco F1 Team | E30: +15 laps
A31: Alexander Albon | B31: {=_xlfn._xlws.FILTER(Drivers!D:D,Drivers!B:B=Table6[[#This Row],[Driver]],0)} -> 23 | C31: =_xlfn.XLOOKUP(A31,Constructor!$C$2:$C$23,Constructor!$B$2:$B$23,"") -> Atlassian Williams-Mercedes | D31: =_xlfn.XLOOKUP(A31,Constructor!$C$2:$C$23,Constructor!$A$2:$A$23,"") -> United Kingdom Atlassian Williams F1 Team | E31: +1 lap
A32: Carlos Sainz Jr. | B32: {=_xlfn._xlws.FILTER(Drivers!D:D,Drivers!B:B=Table6[[#This Row],[Driver]],0)} -> 55 | C32: =_xlfn.XLOOKUP(A32,Constructor!$C$2:$C$23,Constructor!$B$2:$B$23,"") -> Atlassian Williams-Mercedes | D32: =_xlfn.XLOOKUP(A32,Constructor!$C$2:$C$23,Constructor!$A$2:$A$23,"") -> United Kingdom Atlassian Williams F1 Team | E32: +2 laps
A33: Gabriel Bortoleto | B33: {=_xlfn._xlws.FILTER(Drivers!D:D,Drivers!B:B=Table6[[#This Row],[Driver]],0)} -> 5 | C33: =_xlfn.XLOOKUP(A33,Constructor!$C$2:$C$23,Constructor!$B$2:$B$23,"") -> Audi | D33: =_xlfn.XLOOKUP(A33,Constructor!$C$2:$C$23,Constructor!$A$2:$A$23,"") -> Germany Audi Revolut F1 Team | E33: +1 lap
A34: Nico Hülkenberg | B34: {=_xlfn._xlws.FILTER(Drivers!D:D,Drivers!B:B=Table6[[#This Row],[Driver]],0)} -> 27 | C34: =_xlfn.XLOOKUP(A34,Constructor!$C$2:$C$23,Constructor!$B$2:$B$23,"") -> Audi | D34: =_xlfn.XLOOKUP(A34,Constructor!$C$2:$C$23,Constructor!$A$2:$A$23,"") -> Germany Audi Revolut F1 Team | E34: DNS
A35: Sergio Pérez | B35: {=_xlfn._xlws.FILTER(Drivers!D:D,Drivers!B:B=Table6[[#This Row],[Driver]],0)} -> 11 | C35: =_xlfn.XLOOKUP(A35,Constructor!$C$2:$C$23,Constructor!$B$2:$B$23,"") -> Cadillac-Ferrari | D35: =_xlfn.XLOOKUP(A35,Constructor!$C$2:$C$23,Constructor!$A$2:$A$23,"") -> United States Cadillac Formula 1 Team | E35: +3 laps
A36: Valtteri Bottas | B36: {=_xlfn._xlws.FILTER(Drivers!D:D,Drivers!B:B=Table6[[#This Row],[Driver]],0)} -> 77 | C36: =_xlfn.XLOOKUP(A36,Constructor!$C$2:$C$23,Constructor!$B$2:$B$23,"") -> Cadillac-Ferrari | D36: =_xlfn.XLOOKUP(A36,Constructor!$C$2:$C$23,Constructor!$A$2:$A$23,"") -> United States Cadillac Formula 1 Team | E36: DNF
A37: Charles Leclerc | B37: {=_xlfn._xlws.FILTER(Drivers!D:D,Drivers!B:B=Table6[[#This Row],[Driver]],0)} -> 16 | C37: =_xlfn.XLOOKUP(A37,Constructor!$C$2:$C$23,Constructor!$B$2:$B$23,"") -> Ferrari | D37: =_xlfn.XLOOKUP(A37,Constructor!$C$2:$C$23,Constructor!$A$2:$A$23,"") -> Italy Scuderia Ferrari HP | E37: +15.519s
A38: Lewis Hamilton | B38: {=_xlfn._xlws.FILTER(Drivers!D:D,Drivers!B:B=Table6[[#This Row],[Driver]],0)} -> 44 | C38: =_xlfn.XLOOKUP(A38,Constructor!$C$2:$C$23,Constructor!$B$2:$B$23,"") -> Ferrari | D38: =_xlfn.XLOOKUP(A38,Constructor!$C$2:$C$23,Constructor!$A$2:$A$23,"") -> Italy Scuderia Ferrari HP | E38: +16.144s
... A43: Kimi Antonelli | B43: {=_xlfn._xlws.FILTER(Drivers!D:D,Drivers!B:B=Table6[[#This Row],[Driver]],0)} -> 12 | C43: =_xlfn.XLOOKUP(A43,Constructor!$C$2:$C$23,Constructor!$B$2:$B$23,"") -> Mercedes | D43: =_xlfn.XLOOKUP(A43,Constructor!$C$2:$C$23,Constructor!$A$2:$A$23,"") -> Germany Mercedes-AMG Petronas F1 Team | E43: +2.974s
A44: George Russell | B44: {=_xlfn._xlws.FILTER(Drivers!D:D,Drivers!B:B=Table6[[#This Row],[Driver]],0)} -> 63 | C44: =_xlfn.XLOOKUP(A44,Constructor!$C$2:$C$23,Constructor!$B$2:$B$23,"") -> Mercedes | D44: =_xlfn.XLOOKUP(A44,Constructor!$C$2:$C$23,Constructor!$A$2:$A$23,"") -> Germany Mercedes-AMG Petronas F1 Team | E44: 0.057717604
...

Sheet Constructor_Log
A1: Driver | B1: Constructor | C1: Australian Grand Prix | D1: Chinese Grand Prix | E1: Japanese Grand Prix | F1: Bahrain Grand Prix | G1: Saudi Arabian Grand Prix | H1: Miami Grand Prix | I1: Emilia Romagna Grand Prix | J1: Monaco Grand Prix | K1: Spanish Grand Prix | L1: Canadian Grand Prix | M1: Austrian Grand Prix | N1: British Grand Prix | O1: Belgian Grand Prix | P1: Hungarian Grand Prix | Q1: Dutch Grand Prix | R1: Italian Grand Prix | S1: Azerbaijan Grand Prix | T1: Singapore Grand Prix | U1: United States Grand Prix | V1: Mexico City Grand Prix | W1: São Paulo Grand Prix | X1: Las Vegas Grand Prix | Y1: Qatar Grand Prix | Z1: Abu Dhabi Grand Prix
A2: Pierre Gasly | B2: =_xlfn.XLOOKUP(A2,Constructor!$C$2:$C$23,Constructor!$B$2:$B$23,"") -> Alpine-Mercedes
A3: Franco Colapinto | B3: =_xlfn.XLOOKUP(A3,Constructor!$C$2:$C$23,Constructor!$B$2:$B$23,"") -> Alpine-Mercedes
A4: Fernando Alonso | B4: =_xlfn.XLOOKUP(A4,Constructor!$C$2:$C$23,Constructor!$B$2:$B$23,"") -> Aston Martin Aramco-Honda
A5: Lance Stroll | B5: =_xlfn.XLOOKUP(A5,Constructor!$C$2:$C$23,Constructor!$B$2:$B$23,"") -> Aston Martin Aramco-Honda
A6: Alexander Albon | B6: =_xlfn.XLOOKUP(A6,Constructor!$C$2:$C$23,Constructor!$B$2:$B$23,"") -> Atlassian Williams-Mercedes
A7: Carlos Sainz Jr. | B7: =_xlfn.XLOOKUP(A7,Constructor!$C$2:$C$23,Constructor!$B$2:$B$23,"") -> Atlassian Williams-Mercedes
A8: Gabriel Bortoleto | B8: =_xlfn.XLOOKUP(A8,Constructor!$C$2:$C$23,Constructor!$B$2:$B$23,"") -> Audi
A9: Nico Hülkenberg | B9: =_xlfn.XLOOKUP(A9,Constructor!$C$2:$C$23,Constructor!$B$2:$B$23,"") -> Audi
A10: Sergio Pérez | B10: =_xlfn.XLOOKUP(A10,Constructor!$C$2:$C$23,Constructor!$B$2:$B$23,"") -> Cadillac-Ferrari
A11: Valtteri Bottas | B11: =_xlfn.XLOOKUP(A11,Constructor!$C$2:$C$23,Constructor!$B$2:$B$23,"") -> Cadillac-Ferrari
A12: Charles Leclerc | B12: =_xlfn.XLOOKUP(A12,Constructor!$C$2:$C$23,Constructor!$B$2:$B$23,"") -> Ferrari
A13: Lewis Hamilton | B13: =_xlfn.XLOOKUP(A13,Constructor!$C$2:$C$23,Constructor!$B$2:$B$23,"") -> Ferrari
... A23: Isack Hadjar | B23: =_xlfn.XLOOKUP(A23,Constructor!$C$2:$C$23,Constructor!$B$2:$B$23,"") -> Red Bull Racing-Red Bull Ford

Sheet Constructor
A1: Team Name | B1: Constructor | C1: Driver | D1: Engine/Power Unit | E1: Chassis
A2: =_xlfn.XLOOKUP(C2,Drivers!$B$2:$B$23,Drivers!$C$2:$C$23,"") -> France BWT Alpine F1 Team | B2: =_xlfn.XLOOKUP(C2,Drivers!$B$2:$B$23,Drivers!$F$2:$F$23,"") -> Alpine-Mercedes | C2: Pierre Gasly | D2: Mercedes-AMG F1 M17 | E2: A526
A3: =_xlfn.XLOOKUP(C3,Drivers!$B$2:$B$23,Drivers!$C$2:$C$23,"") -> France BWT Alpine F1 Team | B3: =_xlfn.XLOOKUP(C3,Drivers!$B$2:$B$23,Drivers!$F$2:$F$23,"") -> Alpine-Mercedes | C3: Franco Colapinto | D3: Mercedes-AMG F1 M17 | E3: A526
A4: =_xlfn.XLOOKUP(C4,Drivers!$B$2:$B$23,Drivers!$C$2:$C$23,"") -> United Kingdom Aston Martin Aramco F1 Team | B4: =_xlfn.XLOOKUP(C4,Drivers!$B$2:$B$23,Drivers!$F$2:$F$23,"") -> Aston Martin Aramco-Honda | C4: Fernando Alonso | D4: Honda RA626H | E4: AMR26
A5: =_xlfn.XLOOKUP(C5,Drivers!$B$2:$B$23,Drivers!$C$2:$C$23,"") -> United Kingdom Aston Martin Aramco F1 Team | B5: =_xlfn.XLOOKUP(C5,Drivers!$B$2:$B$23,Drivers!$F$2:$F$23,"") -> Aston Martin Aramco-Honda | C5: Lance Stroll | D5: Honda RA626H | E5: AMR26
A6: =_xlfn.XLOOKUP(C6,Drivers!$B$2:$B$23,Drivers!$C$2:$C$23,"") -> United Kingdom Atlassian Williams F1 Team | B6: =_xlfn.XLOOKUP(C6,Drivers!$B$2:$B$23,Drivers!$F$2:$F$23,"") -> Atlassian Williams-Mercedes | C6: Alexander Albon | D6: Mercedes-AMG F1 M17 | E6: FW48
A7: =_xlfn.XLOOKUP(C7,Drivers!$B$2:$B$23,Drivers!$C$2:$C$23,"") -> United Kingdom Atlassian Williams F1 Team | B7: =_xlfn.XLOOKUP(C7,Drivers!$B$2:$B$23,Drivers!$F$2:$F$23,"") -> Atlassian Williams-Mercedes | C7: Carlos Sainz Jr. | D7: Mercedes-AMG F1 M17 | E7: FW48
A8: =_xlfn.XLOOKUP(C8,Drivers!$B$2:$B$23,Drivers!$C$2:$C$23,"") -> Germany Audi Revolut F1 Team | B8: =_xlfn.XLOOKUP(C8,Drivers!$B$2:$B$23,Drivers!$F$2:$F$23,"") -> Audi | C8: Gabriel Bortoleto | D8: Audi AFR 26 Hybrid | E8: R26
A9: =_xlfn.XLOOKUP(C9,Drivers!$B$2:$B$23,Drivers!$C$2:$C$23,"") -> Germany Audi Revolut F1 Team | B9: =_xlfn.XLOOKUP(C9,Drivers!$B$2:$B$23,Drivers!$F$2:$F$23,"") -> Audi | C9: Nico Hülkenberg | D9: Audi AFR 26 Hybrid | E9: R26
A10: =_xlfn.XLOOKUP(C10,Drivers!$B$2:$B$23,Drivers!$C$2:$C$23,"") -> United States Cadillac Formula 1 Team | B10: =_xlfn.XLOOKUP(C10,Drivers!$B$2:$B$23,Drivers!$F$2:$F$23,"") -> Cadillac-Ferrari | C10: Sergio Pérez | D10: Ferrari 067/6 | E10: MAC-26
A11: =_xlfn.XLOOKUP(C11,Drivers!$B$2:$B$23,Drivers!$C$2:$C$23,"") -> United States Cadillac Formula 1 Team | B11: =_xlfn.XLOOKUP(C11,Drivers!$B$2:$B$23,Drivers!$F$2:$F$23,"") -> Cadillac-Ferrari | C11: Valtteri Bottas | D11: Ferrari 067/6 | E11: MAC-26
A12: =_xlfn.XLOOKUP(C12,Drivers!$B$2:$B$23,Drivers!$C$2:$C$23,"") -> Italy Scuderia Ferrari HP | B12: =_xlfn.XLOOKUP(C12,Drivers!$B$2:$B$23,Drivers!$F$2:$F$23,"") -> Ferrari | C12: Charles Leclerc | D12: Ferrari 067/6 | E12: SF-26
A13: =_xlfn.XLOOKUP(C13,Drivers!$B$2:$B$23,Drivers!$C$2:$C$23,"") -> Italy Scuderia Ferrari HP | B13: =_xlfn.XLOOKUP(C13,Drivers!$B$2:$B$23,Drivers!$F$2:$F$23,"") -> Ferrari | C13: Lewis Hamilton | D13: Ferrari 067/6 | E13: SF-26
... A23: =_xlfn.XLOOKUP(C23,Drivers!$B$2:$B$23,Drivers!$C$2:$C$23,"") -> Austria Oracle Red Bull Racing | B23: =_xlfn.XLOOKUP(C23,Drivers!$B$2:$B$23,Drivers!$F$2:$F$23,"") -> Red Bull Racing-Red Bull Ford | C23: Isack Hadjar | D23: Red Bull Ford DM01 | E23: RB22
